Workbook

Sheet Summary Sheet
A2: Project Title | B2: 3-Statement Financial Model
A4: Created by | B4: Antony Rajkumar J
A5: Date | B5: 45973
A7: Objective | B7: To build an integrated 3-statement financial model (Income Statement, Balance Sheet, Cash Flow) for a Juice company using own assumptions.
A9: Model Review | B9: The model projects 5 years (2025–2029) of financial performance based on assumptions like sales growth, cost ratios, and financing activities.
A11: Key Assumptions | B11: Average Revenue growth: 25% per year
B12: Corporate tax rate: 25%
B13: New loan: ₹10,000 in FY2027
A15: Structure | B15: Income Statement
B16: Balance Sheet
B17: Cash Flow Statement
B18: Assumption Table
A20: Formula links | B20: Net profit -- Retained earnings (Equity)
B21: CapEx & Depreciation -- Fixed Assets
B22: Loan assumptions -- Debt & Cash Flow
A24: Note | B24: All figures are in ₹ (INR). Model built for learning purposes.

Sheet Income Statement
A1: INCOME STATEMENT
A2: ₹ in actual figures | B2: 45658 | C2: 46023 | D2: 46388 | E2: =EDATE(D2,12) -> 46753 | F2: =EDATE(E2,12) -> 47119
A3: Revenue
A4: Gross revenue | B4: =B32*B33 -> 700000 | C4: =C32*C33 -> 910000 | D4: =D32*D33 -> 1120000 | E4: =E32*E33 -> 1400000 | F4: =F32*F33 -> 1750000
A5: Discounts | B5: =B4*-B34 -> -35000 | C5: =C4*-C34 -> -45500 | D5: =D4*-D34 -> -56000 | E5: =E4*-E34 -> -70000 | F5: =F4*-F34 -> -87500
A6: Net revenue | B6: =SUM(B4:B5) -> 665000 | C6: =SUM(C4:C5) -> 864500 | D6: =SUM(D4:D5) -> 1064000 | E6: =SUM(E4:E5) -> 1330000 | F6: =SUM(F4:F5) -> 1662500
A7: Cost of goods sold
A8: Raw materials | B8: =-B$4*B37 -> -210000 | C8: =-C$4*C37 -> -273000 | D8: =-D$4*D37 -> -336000 | E8: =-E$4*E37 -> -420000 | F8: =-F$4*F37 -> -525000
A9: Fullfilment | B9: =-B$4*B38 -> -56000 | C9: =-C$4*C38 -> -72800 | D9: =-D$4*D38 -> -89600 | E9: =-E$4*E38 -> -112000 | F9: =-F$4*F38 -> -140000
A10: Transactions fees | B10: =-B$4*B39 -> -21000 | C10: =-C$4*C39 -> -27300 | D10: =-D$4*D39 -> -33600 | E10: =-E$4*E39 -> -42000 | F10: =-F$4*F39 -> -52500
A11: Total COGS | B11: =SUM(B8:B10) -> -287000 | C11: =SUM(C8:C10) -> -373100 | D11: =SUM(D8:D10) -> -459200 | E11: =SUM(E8:E10) -> -574000 | F11: =SUM(F8:F10) -> -717500
A12: Gross profit | B12: =B6+B11 -> 378000 | C12: =C6+C11 -> 491400 | D12: =D6+D11 -> 604800 | E12: =E6+E11 -> 756000 | F12: =F6+F11 -> 945000
A13: Gross profit margin % | B13: =B12/B6 -> 0.56842105 | C13: =C12/C6 -> 0.56842105 | D13: =D12/D6 -> 0.56842105 | E13: =E12/E6 -> 0.56842105 | F13: =F12/F6 -> 0.56842105
A14: Operating expenses
A15: Labor | B15: =-B$4*B42 -> -140000 | C15: =-C$4*C42 -> -182000 | D15: =-D$4*D42 -> -224000 | E15: =-E$4*E42 -> -280000 | F15: =-F$4*F42 -> -350000
A16: Marketing | B16: =-B$4*B43 -> -35000 | C16: =-C$4*C43 -> -45500 | D16: =-D$4*D43 -> -56000 | E16: =-E$4*E43 -> -70000 | F16: =-F$4*F43 -> -87500
A17: SGA & other | B17: =-B$4*B44 -> -35000 | C17: =-C$4*C44 -> -45500 | D17: =-D$4*D44 -> -56000 | E17: =-E$4*E44 -> -70000 | F17: =-F$4*F44 -> -87500
A18: Total op. exp | B18: =SUM(B15:B17) -> -210000 | C18: =SUM(C15:C17) -> -273000 | D18: =SUM(D15:D17) -> -336000 | E18: =SUM(E15:E17) -> -420000 | F18: =SUM(F15:F17) -> -525000
A19: EBITDA | B19: =B12+B18 -> 168000 | C19: =C12+C18 -> 218400 | D19: =D12+D18 -> 268800 | E19: =E12+E18 -> 336000 | F19: =F12+F18 -> 420000
A20: depreciation & Amortization | B20: =-C63 -> -8714.2857 | C20: =-D63 -> -8714.2857 | D20: =-E63 -> -8714.2857 | E20: =-F63 -> -8714.2857 | F20: =-G63 -> -6714.2857
A21: EBIT | B21: =SUM(B19:B20) -> 159285.71 | C21: =SUM(C19:C20) -> 209685.71 | D21: =SUM(D19:D20) -> 260085.71 | E21: =SUM(E19:E20) -> 327285.71 | F21: =SUM(F19:F20) -> 413285.71
A22: Interest expense | B22: =-'Balance Sheet'!C43 -> -6265 | C22: =-'Balance Sheet'!D43 -> -6230 | D22: =-'Balance Sheet'!E43 -> -6877.5 | E22: =-'Balance Sheet'!F43 -> -6825 | F22: =-'Balance Sheet'!G43 -> -6772.5
A23: EBT | B23: =SUM(B21:B22) -> 153020.71 | C23: =SUM(C21:C22) -> 203455.71 | D23: =SUM(D21:D22) -> 253208.21 | E23: =SUM(E21:E22) -> 320460.71 | F23: =SUM(F21:F22) -> 406513.21
A24: Taxes | B24: =-B23*B46 -> -38255.179 | C24: =-C23*C46 -> -50863.929 | D24: =-D23*D46 -> -63302.054 | E24: =-E23*E46 -> -80115.179 | F24: =-F23*F46 -> -101628.3
A25: Net income | B25: =B23+B24 -> 114765.54 | C25: =C23+C24 -> 152591.79 | D25: =D23+D24 -> 189906.16 | E25: =E23+E24 -> 240345.54 | F25: =F23+F24 -> 304884.91
A27: Net income as % of revenue | B27: =B25/B6 -> 0.17257975 | C27: =C25/C6 -> 0.17650872 | D27: =D25/D6 -> 0.17848323 | E27: =E25/E6 -> 0.18071093 | F27: =F25/F6 -> 0.18338942
A30: Assumptions
A31: Revenue | B31: 45658 | C31: 46023 | D31: 46388 | E31: =EDATE(D31,12) -> 46753 | F31: =EDATE(E31,12) -> 47119
A32: cups sold | B32: 10000 | C32: 13000 | D32: 16000 | E32: 20000 | F32: 25000
A33: Average price per cup | B33: 70 | C33: 70 | D33: 70 | E33: 70 | F33: 70
A34: =A5&" as a % of rev" -> Discounts as a % of rev | B34: 0.05 | C34: 0.05 | D34: 0.05 | E34: 0.05 | F34: 0.05
A36: Cost of goods sold
A37: =A8&" as a % of rev" -> Raw materials as a % of rev | B37: 0.3 | C37: 0.3 | D37: 0.3 | E37: 0.3 | F37: 0.3
A38: =A9&" as a % of rev" -> Fullfilment as a % of rev | B38: 0.08 | C38: 0.08 | D38: 0.08 | E38: 0.08 | F38: 0.08
A39: =A10&" as a % of rev" -> Transactions fees as a % of rev | B39: 0.03 | C39: 0.03 | D39: 0.03 | E39: 0.03 | F39: 0.03
A41: Operating expenses
A42: =A15&" as a % of rev" -> Labor as a % of rev | B42: 0.2 | C42: 0.2 | D42: 0.2 | E42: 0.2 | F42: 0.2
A43: =A16&" as a % of rev" -> Marketing as a % of rev | B43: 0.05 | C43: 0.05 | D43: 0.05 | E43: 0.05 | F43: 0.05
A44: =A17&" as a % of rev" -> SGA & other as a % of rev | B44: 0.05 | C44: 0.05 | D44: 0.05 | E44: 0.05 | F44: 0.05
A46: Corporate tax rate | B46: 0.25 | C46: 0.25 | D46: 0.25 | E46: 0.25 | F46: 0.25
...

Sheet Balance Sheet
A1: Balance Sheet | B1: Historical
A2: ₹ in actual figures | B2: 45657 | C2: 46022 | D2: 46387 | E2: 46752 | F2: 47118 | G2: 47483
A4: Current assets
A5: Cash | B5: 437000 | C5: =B5+'Cashflow Statement'!B18 -> 518467.04 | D5: =C5+'Cashflow Statement'!C18 -> 680454.28 | E5: =D5+'Cashflow Statement'!D18 -> 889505.89 | F5: =E5+'Cashflow Statement'!E18 -> 1136390.6 | G5: =F5+'Cashflow Statement'!F18 -> 1449208.4
A6: Accounts receivable | B6: 150 | C6: =C35*C33 -> 237.5 | D6: =D35*D33 -> 308.75 | E6: =E35*E33 -> 380 | F6: =F35*F33 -> 475 | G6: =G35*G33 -> 593.75
A7: Total current assets | B7: =SUM(B5:B6) -> 437150 | C7: =SUM(C5:C6) -> 518704.54 | D7: =SUM(D5:D6) -> 680763.03 | E7: =SUM(E5:E6) -> 889885.89 | F7: =SUM(F5:F6) -> 1136865.6 | G7: =SUM(G5:G6) -> 1449802.2
A8: Non currrent assets
A9: Fixed assets | B9: 10000 | C9: =B9+'Income Statement'!C56 -> 53000 | D9: =C9+'Income Statement'!D56 -> 53000 | E9: =D9+'Income Statement'!E56 -> 53000 | F9: =E9+'Income Statement'!F56 -> 56000 | G9: =F9+'Income Statement'!G56 -> 56000
A10: Accumulated depreciation | B10: =-'Income Statement'!C59 -> -2000 | C10: =B10-'Income Statement'!C63 -> -10714.286 | D10: =C10-'Income Statement'!D63 -> -19428.571 | E10: =D10-'Income Statement'!E63 -> -28142.857 | F10: =E10-'Income Statement'!F63 -> -36857.143 | G10: =F10-'Income Statement'!G63 -> -43571.429
A11: Net fixed assets | B11: =SUM(B9:B10) -> 8000 | C11: =SUM(C9:C10) -> 42285.714 | D11: =SUM(D9:D10) -> 33571.429 | E11: =SUM(E9:E10) -> 24857.143 | F11: =SUM(F9:F10) -> 19142.857 | G11: =SUM(G9:G10) -> 12428.571
A12: Total non current assets | B12: =B11 -> 8000 | C12: =C11 -> 42285.714 | D12: =D11 -> 33571.429 | E12: =E11 -> 24857.143 | F12: =F11 -> 19142.857 | G12: =G11 -> 12428.571
A13: Total assets | B13: =B7+B12 -> 445150 | C13: =C7+C12 -> 560990.25 | D13: =D7+D12 -> 714334.46 | E13: =E7+E12 -> 914743.03 | F13: =F7+F12 -> 1156008.5 | G13: =G7+G12 -> 1462230.7
A15: Current liabilities
A16: Accounts payable | B16: 2000 | C16: =C36*C34 -> 3224.7191 | D16: =D36*D34 -> 4192.1348 | E16: =E36*E34 -> 5159.5506 | F16: =F36*F34 -> 6449.4382 | G16: =G36*G34 -> 8061.7978
A17: Deferred revenue | B17: 600 | C17: =C37*C33 -> 950 | D17: =D37*D33 -> 1235 | E17: =E37*E33 -> 1520 | F17: =F37*F33 -> 1900 | G17: =G37*G33 -> 2375
A18: Total current liabilities | B18: =SUM(B16:B17) -> 2600 | C18: =SUM(C16:C17) -> 4174.7191 | D18: =SUM(D16:D17) -> 5427.1348 | E18: =SUM(E16:E17) -> 6679.5506 | F18: =SUM(F16:F17) -> 8349.4382 | G18: =SUM(G16:G17) -> 10436.798
A19: Non current liabilities | B19: =SUM(B18) -> 2600 | C19: =SUM(C18) -> 4174.7191 | D19: =SUM(D18) -> 5427.1348 | E19: =SUM(E18) -> 6679.5506 | F19: =SUM(F18) -> 8349.4382 | G19: =SUM(G18) -> 10436.798
A20: Debt | B20: 90000 | C20: =B20+C40-C41 -> 89500 | D20: =C20+D40-D41 -> 89000 | E20: =D20+E40-E41 -> 98250 | F20: =E20+F40-F41 -> 97500 | G20: =F20+G40-G41 -> 96750
A21: Total non current liabilities | B21: =B20 -> 90000 | C21: =C20 -> 89500 | D21: =D20 -> 89000 | E21: =E20 -> 98250 | F21: =F20 -> 97500 | G21: =G20 -> 96750
A22: Total liabilities | B22: =B21+B18 -> 92600 | C22: =C21+C18 -> 93674.719 | D22: =D21+D18 -> 94427.135 | E22: =E21+E18 -> 104929.55 | F22: =F21+F18 -> 105849.44 | G22: =G21+G18 -> 107186.8
A23: Equity
A24: Common stock | B24: 100000 | C24: =B24 -> 100000 | D24: =C24 -> 100000 | E24: =D24 -> 100000 | F24: =E24 -> 100000 | G24: =F24 -> 100000
A25: Retained earnings | B25: 252550 | C25: =B25+'Income Statement'!B25 -> 367315.54 | D25: =C25+'Income Statement'!C25 -> 519907.32 | E25: =D25+'Income Statement'!D25 -> 709813.48 | F25: =E25+'Income Statement'!E25 -> 950159.02 | G25: =F25+'Income Statement'!F25 -> 1255043.9
A26: Total equity | B26: =SUM(B24:B25) -> 352550 | C26: =SUM(C24:C25) -> 467315.54 | D26: =SUM(D24:D25) -> 619907.32 | E26: =SUM(E24:E25) -> 809813.48 | F26: =SUM(F24:F25) -> 1050159 | G26: =SUM(G24:G25) -> 1355043.9
A27: Total libalities & equity | B27: =B26+B22 -> 445150 | C27: =C26+C22 -> 560990.25 | D27: =D26+D22 -> 714334.46 | E27: =E26+E22 -> 914743.03 | F27: =F26+F22 -> 1156008.5 | G27: =G26+G22 -> 1462230.7
A29: Balance check | B29: =B27-B13 -> 0 | C29: =C27-C13 -> 0 | D29: =D27-D13 -> 0 | E29: =E27-E13 -> 0 | F29: =F27-F13 -> 0 | G29: =G27-G13 -> 0
A32: Assumptions
A33: Net revenue | B33: 420000 | C33: ='Income Statement'!B6 -> 665000 | D33: ='Income Statement'!C6 -> 864500 | E33: ='Income Statement'!D6 -> 1064000 | F33: ='Income Statement'!E6 -> 1330000 | G33: ='Income Statement'!F6 -> 1662500
A34: COGS | B34: 178000 | C34: =-'Income Statement'!B11 -> 287000 | D34: =-'Income Statement'!C11 -> 373100 | E34: =-'Income Statement'!D11 -> 459200 | F34: =-'Income Statement'!E11 -> 574000 | G34: =-'Income Statement'!F11 -> 717500
A35: =A6&" as a % of rev" -> Accounts receivable as a % of rev | B35: =B6/B33 -> 0.00035714286 | C35: =B35 -> 0.00035714286 | D35: =C35 -> 0.00035714286 | E35: =D35 -> 0.00035714286 | F35: =E35 -> 0.00035714286 | G35: =F35 -> 0.00035714286
A36: =A16& " as % of COGS" -> Accounts payable as % of COGS | B36: =B16/B34 -> 0.011235955 | C36: =B36 -> 0.011235955 | D36: =C36 -> 0.011235955 | E36: =D36 -> 0.011235955 | F36: =E36 -> 0.011235955 | G36: =F36 -> 0.011235955
A37: =A17& " as % of rev" -> Deferred revenue as % of rev | B37: =B17/B33 -> 0.0014285714 | C37: =B37 -> 0.0014285714 | D37: =C37 -> 0.0014285714 | E37: =D37 -> 0.0014285714 | F37: =E37 -> 0.0014285714 | G37: =F37 -> 0.0014285714
A39: Debt
A40: Net borrowing | E40: 10000
A41: Debt repayment | C41: 500 | D41: 500 | E41: 750 | F41: 750 | G41: 750
A42: Interest rate | C42: 0.07 | D42: 0.07 | E42: 0.07 | F42: 0.07 | G42: 0.07
A43: Interest payment | C43: =C42*C20 -> 6265 | D43: =D42*D20 -> 6230 | E43: =E42*E20 -> 6877.5 | F43: =F42*F20 -> 6825 | G43: =G42*G20 -> 6772.5

Sheet Cashflow Statement
A1: Cashflow Statement
A2: ₹ in actual figures | B2: 45658 | C2: 46023 | D2: 46388 | E2: 46753 | F2: 47119
A4: Net income | B4: ='Income Statement'!B25 -> 114765.54 | C4: ='Income Statement'!C25 -> 152591.79 | D4: ='Income Statement'!D25 -> 189906.16 | E4: ='Income Statement'!E25 -> 240345.54 | F4: ='Income Statement'!F25 -> 304884.91
A5: Operating activities
A6: Depreciation | B6: ='Income Statement'!C63 -> 8714.2857 | C6: ='Income Statement'!D63 -> 8714.2857 | D6: ='Income Statement'!E63 -> 8714.2857 | E6: ='Income Statement'!F63 -> 8714.2857 | F6: ='Income Statement'!G63 -> 6714.2857
A7: Change in Acc.Rec | B7: =-('Balance Sheet'!C6-'Balance Sheet'!B6) -> -87.5 | C7: =-('Balance Sheet'!D6-'Balance Sheet'!C6) -> -71.25 | D7: =-('Balance Sheet'!E6-'Balance Sheet'!D6) -> -71.25 | E7: =-('Balance Sheet'!F6-'Balance Sheet'!E6) -> -95 | F7: =-('Balance Sheet'!G6-'Balance Sheet'!F6) -> -118.75
A8: Change in Acc.Pay | B8: ='Balance Sheet'!C16-'Balance Sheet'!B16 -> 1224.7191 | C8: ='Balance Sheet'!D16-'Balance Sheet'!C16 -> 967.41573 | D8: ='Balance Sheet'!E16-'Balance Sheet'!D16 -> 967.41573 | E8: ='Balance Sheet'!F16-'Balance Sheet'!E16 -> 1289.8876 | F8: ='Balance Sheet'!G16-'Balance Sheet'!F16 -> 1612.3596
A9: Change in Def.Rev | B9: ='Balance Sheet'!C17-'Balance Sheet'!B17 -> 350 | C9: ='Balance Sheet'!D17-'Balance Sheet'!C17 -> 285 | D9: ='Balance Sheet'!E17-'Balance Sheet'!D17 -> 285 | E9: ='Balance Sheet'!F17-'Balance Sheet'!E17 -> 380 | F9: ='Balance Sheet'!G17-'Balance Sheet'!F17 -> 475
A10: Operating cash flow | B10: =SUM(B6:B9) -> 10201.505 | C10: =SUM(C6:C9) -> 9895.4514 | D10: =SUM(D6:D9) -> 9895.4514 | E10: =SUM(E6:E9) -> 10289.173 | F10: =SUM(F6:F9) -> 8682.8953
A11: Investing Activities
A12: Cap.Exp | B12: =-'Income Statement'!C56 -> -43000 | C12: =-'Income Statement'!D56 -> 0 | D12: =-'Income Statement'!E56 -> 0 | E12: =-'Income Statement'!F56 -> -3000 | F12: =-'Income Statement'!G56 -> 0
A13: Investing cash flow | B13: =B12 -> -43000 | C13: =C12 -> 0 | D13: =D12 -> 0 | E13: =E12 -> -3000 | F13: =F12 -> 0
A14: Financing activities
A15: Debt repayment | B15: =-'Balance Sheet'!C41 -> -500 | C15: =-'Balance Sheet'!D41 -> -500 | D15: =-'Balance Sheet'!E41 -> -750 | E15: =-'Balance Sheet'!F41 -> -750 | F15: =-'Balance Sheet'!G41 -> -750
A16: Net borrowings | B16: ='Balance Sheet'!C40 -> 0 | C16: ='Balance Sheet'!D40 -> 0 | D16: ='Balance Sheet'!E40 -> 10000 | E16: ='Balance Sheet'!F40 -> 0 | F16: ='Balance Sheet'!G40 -> 0
A17: Financing cash flow | B17: =SUM(B15:B16) -> -500 | C17: =SUM(C15:C16) -> -500 | D17: =SUM(D15:D16) -> 9250 | E17: =SUM(E15:E16) -> -750 | F17: =SUM(F15:F16) -> -750
A18: Net cash flow | B18: =B4+B10+B13+B17 -> 81467.041 | C18: =C4+C10+C13+C17 -> 161987.24 | D18: =D4+D10+D13+D17 -> 209051.61 | E18: =E4+E10+E13+E17 -> 246884.71 | F18: =F4+F10+F13+F17 -> 312817.81
